<?xml version="1.0"?>
<robot name="visual">

  <material name="blue">
    <color rgba="0 0 0.8 1"/>
  </material>
  <material name="black">
    <color rgba="0 0 0 1"/>
  </material>
  <material name="white">
    <color rgba="1 1 1 1"/>
  </material>

  <link name="base_link">
    <visual>
      <geometry>
        <cylinder length="0.1" radius="0.25"/>
      </geometry>
      <material name="black"/>
    </visual>
  </link>

  <link name="head">
    <visual>
      <geometry>
        <cylinder length="0.2" radius="0.2"/>
      </geometry>
      <origin xyz="0 0 0.1"/>
      <material name="blue"/>
    </visual>
  </link>

  <joint name="base_to_head" type="continuous">
    <parent link="base_link"/>
    <child link="head"/>
    <axis xyz="0 0 1"/>
    <origin xyz="0 0 0.05"/>
  </joint>

  <link name="first_cyn">
    <visual>
      <geometry>
        <cylinder length="0.1" radius="0.1"/>
      </geometry>  
      <origin xyz="0 0 0" rpy="1.57075 0 0"/>
      <material name="blue"/>
    </visual>
  </link>

  <joint name="head_to_first" type="continuous">
    <parent link="head"/>
    <child link="first_cyn"/>
    <origin xyz="0 0.2 0.1"/>
    <axis xyz="0 1 0"/>
  </joint>

  <link name="link1">
     <visual>
       <geometry>
         <cylinder length="0.5" radius="0.05"/>
       </geometry>
       <origin xyz="0 0.25 0" rpy="1.57075 0 0"/>
       <material name="white"/>
     </visual>
  </link>

  <joint name="first_to_link1" type="fixed">
    <parent link="first_cyn"/>
    <child link="link1"/>
    <origin xyz="0 0.05 0"/>
  </joint>

  <link name="third_cyn">
     <visual>
      <geometry>
        <cylinder length="0.15" radius="0.05"/>
      </geometry>  
      <origin xyz="0 0 0" rpy="0 1.57075 0"/>
      <material name="blue"/>
    </visual>
  </link>

  <joint name="link1_to_third" type="continuous">
    <parent link="link1"/>
    <child link="third_cyn"/>
    <origin xyz="0 0.5 0"/>
    <axis xyz="1 0 0"/>
  </joint>

  <link name="link2">
     <visual>
       <geometry>
         <cylinder length="0.5" radius="0.05"/>
       </geometry>
       <origin xyz="0 0.25 0" rpy="1.57075 0 0"/>
       <material name="white"/>
     </visual>
  </link>
  
  <joint name="third_to_link2" type="fixed">
    <parent link="third_cyn"/>
    <child link="link2"/>
    <origin xyz="0.075 0 0"/>
  </joint>
</robot>
